<?xml version="1.0" ?>
<!-- =================================================================================== -->
<!-- |    This document was autogenerated by xacro from robot.xacro                    | -->
<!-- |    EDITING THIS FILE BY HAND IS NOT RECOMMENDED                                 | -->
<!-- =================================================================================== -->
<robot name="physics">
  <material name="blue">
    <color rgba="0 0 0.8 1"/>
  </material>
  <material name="black">
    <color rgba="0 0 0 1"/>
  </material>
  <material name="white">
    <color rgba="1 1 1 1"/>
  </material>
  <material name="pink">
    <color rgba="1 0.7 0.85 1"/>
  </material>
  <material name="light_pink">
    <color rgba="1 0.9 0.99 1"/>
  </material>
  <material name="dark_pink">
    <color rgba="0.7 0.5 0.6 1"/>
  </material>
  <link name="base_link">
    <visual>
      <geometry>
        <cylinder length="0.5" radius="0.2"/>
      </geometry>
      <material name="pink"/>
      <origin rpy="1.5708 0 1.5708" xyz="0 0 0"/>
    </visual>
    <collision>
      <geometry>
        <cylinder length="0.5" radius="0.2"/>
      </geometry>
      <origin rpy="1.5708 0 1.5708" xyz="0 0 0"/>
    </collision>
    <inertial>
      <mass value="1"/>
      <inertia ixx="1e-3" ixy="0" ixz="0" iyy="1e-3" iyz="0" izz="1e-3"/>
    </inertial>
  </link>
  <link name="right_top_leg">
    <visual>
      <geometry>
        <box size="0.1 0.1 0.3"/>
      </geometry>
      <material name="light_pink"/>
      <origin rpy="0 0 0" xyz="0.175 -0.2 -0.1"/>
    </visual>
    <collision>
      <geometry>
        <box size="0.1 0.1 0.3"/>
      </geometry>
      <origin rpy="0 0 0" xyz="0.175 -0.2 -0.1"/>
    </collision>
    <inertial>
      <mass value="10"/>
      <inertia ixx="1e-3" ixy="0" ixz="0" iyy="1e-3" iyz="0" izz="1e-3"/>
    </inertial>
  </link>
  <joint name="base_link_to_right_top_leg" type="fixed">
    <parent link="base_link"/>
    <child link="right_top_leg"/>
    <origin rpy="0 0 0" xyz="0 0 0"/>
  </joint>
  <link name="right_back_leg">
    <visual>
      <geometry>
        <box size="0.1 0.1 0.3"/>
      </geometry>
      <material name="light_pink"/>
      <origin rpy="0 0 0" xyz="-0.175 -0.2 -0.1"/>
    </visual>
    <collision>
      <geometry>
        <box size="0.1 0.1 0.3"/>
      </geometry>
      <origin rpy="0 0 0" xyz="-0.175 -0.2 -0.1"/>
    </collision>
    <inertial>
      <mass value="10"/>
      <inertia ixx="1e-3" ixy="0" ixz="0" iyy="1e-3" iyz="0" izz="1e-3"/>
    </inertial>
  </link>
  <joint name="base_link_to_right_back_leg" type="fixed">
    <parent link="base_link"/>
    <child link="right_back_leg"/>
    <origin rpy="0 0 0" xyz="0 0 0"/>
  </joint>
  <link name="left_top_leg">
    <visual>
      <geometry>
        <box size="0.1 0.1 0.3"/>
      </geometry>
      <material name="light_pink"/>
      <origin rpy="0 0 0" xyz="0.175 0.2 -0.1"/>
    </visual>
    <collision>
      <geometry>
        <box size="0.1 0.1 0.3"/>
      </geometry>
      <origin rpy="0 0 0" xyz="0.175 0.2 -0.1"/>
    </collision>
    <inertial>
      <mass value="10"/>
      <inertia ixx="1e-3" ixy="0" ixz="0" iyy="1e-3" iyz="0" izz="1e-3"/>
    </inertial>
  </link>
  <joint name="base_link_to_left_top_leg" type="fixed">
    <parent link="base_link"/>
    <child link="left_top_leg"/>
    <origin rpy="0 0 0" xyz="0 0 0"/>
  </joint>
  <link name="left_back_leg">
    <visual>
      <geometry>
        <box size="0.1 0.1 0.3"/>
      </geometry>
      <material name="light_pink"/>
      <origin rpy="0 0 0" xyz="-0.175 0.2 -0.1"/>
    </visual>
    <collision>
      <geometry>
        <box size="0.1 0.1 0.3"/>
      </geometry>
      <origin rpy="0 0 0" xyz="-0.175 0.2 -0.1"/>
    </collision>
    <inertial>
      <mass value="10"/>
      <inertia ixx="1e-3" ixy="0" ixz="0" iyy="1e-3" iyz="0" izz="1e-3"/>
    </inertial>
  </link>
  <joint name="base_link_to_left_back_leg" type="fixed">
    <parent link="base_link"/>
    <child link="left_back_leg"/>
    <origin rpy="0 0 0" xyz="0 0 0"/>
  </joint>
  <link name="right_front_wheel">
    <visual>
      <geometry>
        <cylinder length="0.1" radius="0.04"/>
      </geometry>
      <material name="black"/>
      <origin rpy="1.57075 0 0" xyz="0 0 0"/>
    </visual>
    <collision>
      <geometry>
        <cylinder length="0.1" radius="0.04"/>
      </geometry>
      <origin rpy="1.57075 0 0" xyz="0 0 0"/>
    </collision>
    <inertial>
      <mass value="1"/>
      <inertia ixx="1e-3" ixy="0" ixz="0" iyy="1e-3" iyz="0" izz="1e-3"/>
    </inertial>
  </link>
  <joint name="right_front_wheel_joint" type="continuous">
    <axis xyz="0 1 0"/>
    <parent link="right_top_leg"/>
    <child link="right_front_wheel"/>
    <origin rpy="0 0 0" xyz="0.175 -0.2 -0.29"/>
  </joint>
</robot>
